Workbook

Sheet Total
A1: Jahr | B1: Monat | C1: saison | D1: Temperatur (C°) | E1: Stromerzeugnisse | F1: Stromverbrauch | G1: Bevölkerung | H1: Stromverbrauch pro kopf | I1: Heizbedarf | J1: Deckungsgrad | K1: Strombilanz
A2: =1990+INT((ROW(A1)-1)/12) -> 1990 | B2: jan | C2: =IF(OR(B2="dec",B2="jan",B2="feb"),"Winter",IF(OR(B2="mar",B2="apr",B2="may"),"Frühling",IF(OR(B2="jun",B2="jul",B2="aug"),"Sommer","Herbst"))) -> Winter | D2: =INDEX(Wetter!B:M,MATCH(A2,Wetter!A:A,0),MATCH(B2,Wetter!B$1:M$1,0)) -> -1.67 | E2: 4328 | F2: 4589 | G2: =_xlfn.XLOOKUP(A2,Bevölkerung!A:A,Bevölkerung!B:B) -> 6750693 | H2: =G2/F2 -> 1471.0597 | I2: =F2/(20-D2) -> 211.76742 | J2: =E2/F2 -> 0.94312486 | K2: =E2-F2 -> -261
A3: =1990+INT((ROW(A2)-1)/12) -> 1990 | B3: feb | C3: =IF(OR(B3="dec",B3="jan",B3="feb"),"Winter",IF(OR(B3="mar",B3="apr",B3="may"),"Frühling",IF(OR(B3="jun",B3="jul",B3="aug"),"Sommer","Herbst"))) -> Winter | D3: =INDEX(Wetter!B:M,MATCH(A3,Wetter!A:A,0),MATCH(B3,Wetter!B$1:M$1,0)) -> 2.1 | E3: 3929 | F3: 3921 | G3: =_xlfn.XLOOKUP(A3,Bevölkerung!A:A,Bevölkerung!B:B) -> 6750693 | H3: =G3/F3 -> 1721.6764 | I3: =F3/(20-D3) -> 219.05028 | J3: =E3/F3 -> 1.0020403 | K3: =E3-F3 -> 8
A4: =1990+INT((ROW(A3)-1)/12) -> 1990 | B4: mar | C4: =IF(OR(B4="dec",B4="jan",B4="feb"),"Winter",IF(OR(B4="mar",B4="apr",B4="may"),"Frühling",IF(OR(B4="jun",B4="jul",B4="aug"),"Sommer","Herbst"))) -> Frühling | D4: =INDEX(Wetter!B:M,MATCH(A4,Wetter!A:A,0),MATCH(B4,Wetter!B$1:M$1,0)) -> 2.76 | E4: 4736 | F4: 4157 | G4: =_xlfn.XLOOKUP(A4,Bevölkerung!A:A,Bevölkerung!B:B) -> 6750693 | H4: =G4/F4 -> 1623.9338 | I4: =F4/(20-D4) -> 241.12529 | J4: =E4/F4 -> 1.1392831 | K4: =E4-F4 -> 579
A5: =1990+INT((ROW(A4)-1)/12) -> 1990 | B5: apr | C5: =IF(OR(B5="dec",B5="jan",B5="feb"),"Winter",IF(OR(B5="mar",B5="apr",B5="may"),"Frühling",IF(OR(B5="jun",B5="jul",B5="aug"),"Sommer","Herbst"))) -> Frühling | D5: =INDEX(Wetter!B:M,MATCH(A5,Wetter!A:A,0),MATCH(B5,Wetter!B$1:M$1,0)) -> 2.52 | E5: 4397 | F5: 3796 | G5: =_xlfn.XLOOKUP(A5,Bevölkerung!A:A,Bevölkerung!B:B) -> 6750693 | H5: =G5/F5 -> 1778.3701 | I5: =F5/(20-D5) -> 217.16247 | J5: =E5/F5 -> 1.1583246 | K5: =E5-F5 -> 601
A6: =1990+INT((ROW(A5)-1)/12) -> 1990 | B6: may | C6: =IF(OR(B6="dec",B6="jan",B6="feb"),"Winter",IF(OR(B6="mar",B6="apr",B6="may"),"Frühling",IF(OR(B6="jun",B6="jul",B6="aug"),"Sommer","Herbst"))) -> Frühling | D6: =INDEX(Wetter!B:M,MATCH(A6,Wetter!A:A,0),MATCH(B6,Wetter!B$1:M$1,0)) -> 9.79 | E6: 4897 | F6: 3581 | G6: =_xlfn.XLOOKUP(A6,Bevölkerung!A:A,Bevölkerung!B:B) -> 6750693 | H6: =G6/F6 -> 1885.1419 | I6: =F6/(20-D6) -> 350.73457 | J6: =E6/F6 -> 1.3674951 | K6: =E6-F6 -> 1316
A7: =1990+INT((ROW(A6)-1)/12) -> 1990 | B7: jun | C7: =IF(OR(B7="dec",B7="jan",B7="feb"),"Winter",IF(OR(B7="mar",B7="apr",B7="may"),"Frühling",IF(OR(B7="jun",B7="jul",B7="aug"),"Sommer","Herbst"))) -> Sommer | D7: =INDEX(Wetter!B:M,MATCH(A7,Wetter!A:A,0),MATCH(B7,Wetter!B$1:M$1,0)) -> 10.69 | E7: 4623 | F7: 3513 | G7: =_xlfn.XLOOKUP(A7,Bevölkerung!A:A,Bevölkerung!B:B) -> 6750693 | H7: =G7/F7 -> 1921.6319 | I7: =F7/(20-D7) -> 377.3362 | J7: =E7/F7 -> 1.3159693 | K7: =E7-F7 -> 1110
A8: =1990+INT((ROW(A7)-1)/12) -> 1990 | B8: jul | C8: =IF(OR(B8="dec",B8="jan",B8="feb"),"Winter",IF(OR(B8="mar",B8="apr",B8="may"),"Frühling",IF(OR(B8="jun",B8="jul",B8="aug"),"Sommer","Herbst"))) -> Sommer | D8: =INDEX(Wetter!B:M,MATCH(A8,Wetter!A:A,0),MATCH(B8,Wetter!B$1:M$1,0)) -> 14.06 | E8: 5223 | F8: 3346 | G8: =_xlfn.XLOOKUP(A8,Bevölkerung!A:A,Bevölkerung!B:B) -> 6750693 | H8: =G8/F8 -> 2017.5412 | I8: =F8/(20-D8) -> 563.29966 | J8: =E8/F8 -> 1.5609683 | K8: =E8-F8 -> 1877
A9: =1990+INT((ROW(A8)-1)/12) -> 1990 | B9: aug | C9: =IF(OR(B9="dec",B9="jan",B9="feb"),"Winter",IF(OR(B9="mar",B9="apr",B9="may"),"Frühling",IF(OR(B9="jun",B9="jul",B9="aug"),"Sommer","Herbst"))) -> Sommer | D9: =INDEX(Wetter!B:M,MATCH(A9,Wetter!A:A,0),MATCH(B9,Wetter!B$1:M$1,0)) -> 14.31 | E9: 4068 | F9: 3373 | G9: =_xlfn.XLOOKUP(A9,Bevölkerung!A:A,Bevölkerung!B:B) -> 6750693 | H9: =G9/F9 -> 2001.3913 | I9: =F9/(20-D9) -> 592.79438 | J9: =E9/F9 -> 1.206048 | K9: =E9-F9 -> 695
A10: =1990+INT((ROW(A9)-1)/12) -> 1990 | B10: sep | C10: =IF(OR(B10="dec",B10="jan",B10="feb"),"Winter",IF(OR(B10="mar",B10="apr",B10="may"),"Frühling",IF(OR(B10="jun",B10="jul",B10="aug"),"Sommer","Herbst"))) -> Herbst | D10: =INDEX(Wetter!B:M,MATCH(A10,Wetter!A:A,0),MATCH(B10,Wetter!B$1:M$1,0)) -> 9.4 | E10: 4229 | F10: 3526 | G10: =_xlfn.XLOOKUP(A10,Bevölkerung!A:A,Bevölkerung!B:B) -> 6750693 | H10: =G10/F10 -> 1914.5471 | I10: =F10/(20-D10) -> 332.64151 | J10: =E10/F10 -> 1.1993761 | K10: =E10-F10 -> 703
A11: =1990+INT((ROW(A10)-1)/12) -> 1990 | B11: oct | C11: =IF(OR(B11="dec",B11="jan",B11="feb"),"Winter",IF(OR(B11="mar",B11="apr",B11="may"),"Frühling",IF(OR(B11="jun",B11="jul",B11="aug"),"Sommer","Herbst"))) -> Herbst | D11: =INDEX(Wetter!B:M,MATCH(A11,Wetter!A:A,0),MATCH(B11,Wetter!B$1:M$1,0)) -> 7.85 | E11: 4500 | F11: 3967 | G11: =_xlfn.XLOOKUP(A11,Bevölkerung!A:A,Bevölkerung!B:B) -> 6750693 | H11: =G11/F11 -> 1701.7124 | I11: =F11/(20-D11) -> 326.50206 | J11: =E11/F11 -> 1.1343585 | K11: =E11-F11 -> 533
A12: =1990+INT((ROW(A11)-1)/12) -> 1990 | B12: nov | C12: =IF(OR(B12="dec",B12="jan",B12="feb"),"Winter",IF(OR(B12="mar",B12="apr",B12="may"),"Frühling",IF(OR(B12="jun",B12="jul",B12="aug"),"Sommer","Herbst"))) -> Herbst | D12: =INDEX(Wetter!B:M,MATCH(A12,Wetter!A:A,0),MATCH(B12,Wetter!B$1:M$1,0)) -> 0.4 | E12: 4590 | F12: 4299 | G12: =_xlfn.XLOOKUP(A12,Bevölkerung!A:A,Bevölkerung!B:B) -> 6750693 | H12: =G12/F12 -> 1570.2938 | I12: =F12/(20-D12) -> 219.33673 | J12: =E12/F12 -> 1.0676902 | K12: =E12-F12 -> 291
A13: =1990+INT((ROW(A12)-1)/12) -> 1990 | B13: dec | C13: =IF(OR(B13="dec",B13="jan",B13="feb"),"Winter",IF(OR(B13="mar",B13="apr",B13="may"),"Frühling",IF(OR(B13="jun",B13="jul",B13="aug"),"Sommer","Herbst"))) -> Winter | D13: =INDEX(Wetter!B:M,MATCH(A13,Wetter!A:A,0),MATCH(B13,Wetter!B$1:M$1,0)) -> -3.79 | E13: 4554 | F13: 4510 | G13: =_xlfn.XLOOKUP(A13,Bevölkerung!A:A,Bevölkerung!B:B) -> 6750693 | H13: =G13/F13 -> 1496.8277 | I13: =F13/(20-D13) -> 189.57545 | J13: =E13/F13 -> 1.0097561 | K13: =E13-F13 -> 44
... A434: =1990+INT((ROW(A433)-1)/12) -> 2026 | B434: jan | C434: =IF(OR(B434="dec",B434="jan",B434="feb"),"Winter",IF(OR(B434="mar",B434="apr",B434="may"),"Frühling",IF(OR(B434="jun",B434="jul",B434="aug"),"Sommer","Herbst"))) -> Winter | D434: =INDEX(Wetter!B:M,MATCH(A434,Wetter!A:A,0),MATCH(B434,Wetter!B$1:M$1,0)) -> -2.68 | E434: 4911 | F434: 5983 | G434: =_xlfn.XLOOKUP(A434,Bevölkerung!A:A,Bevölkerung!B:B) -> #N/A | H434: =G434/F434 -> #N/A | I434: =F434/(20-D434) -> 263.80071 | J434: =E434/F434 -> 0.82082567 | K434: =E434-F434 -> -1072

Sheet Wetter
A1: time | B1: jan | C1: feb | D1: mar | E1: apr | F1: may | G1: jun | H1: jul | I1: aug | J1: sep | K1: oct | L1: nov | M1: dec | N1: djf | O1: mam | P1: jja | Q1: son | R1: winter | S1: summer | T1: year
A2: 1864 | B2: -7.1 | C2: -4.52 | D2: 0.04 | E2: 2.1 | F2: 7.43 | G2: 9.48 | H2: 12.37 | I2: 10.95 | J2: 8.59 | K2: 3.51 | L2: -0.51 | M2: -4.47 | N2: NA | O2: 3.19 | P2: 10.93 | Q2: 3.86 | R2: NA | S2: 8.49 | T2: 3.16
A3: 1865 | B3: -3.46 | C3: -6.26 | D3: -5.91 | E3: 7.01 | F3: 10.1 | G3: 10.98 | H3: 13.98 | I3: 11.16 | J3: 11.89 | K3: 5.21 | L3: 1.26 | M3: -3.07 | N3: -4.73 | O3: 3.73 | P3: 12.04 | Q3: 6.12 | R3: -2.85 | S3: 10.85 | T3: 4.41
A4: 1866 | B4: -1.31 | C4: -0.42 | D4: -1 | E4: 4.1 | F4: 4.96 | G4: 12.02 | H4: 12.25 | I4: 9.99 | J4: 9.69 | K4: 5.35 | L4: -0.2 | M4: -0.49 | N4: -1.6 | O4: 2.68 | P4: 11.42 | Q4: 4.95 | R4: 0.11 | S4: 8.83 | T4: 4.58
A5: 1867 | B5: -3.87 | C5: 0.55 | D5: -0.13 | E5: 3.48 | F5: 7.74 | G5: 10.57 | H5: 11.29 | I5: 12.94 | J5: 10.42 | K5: 2.93 | L5: -1.43 | M5: -5.8 | N5: -1.27 | O5: 3.69 | P5: 11.6 | Q5: 3.97 | R5: 0.2 | S5: 9.41 | T5: 4.06
A6: 1868 | B6: -5.46 | C6: -1.54 | D6: -2.3 | E6: 2.32 | F6: 12.04 | G6: 11.96 | H6: 12.88 | I6: 12.5 | J6: 11.12 | K6: 4.78 | L6: -1.99 | M6: 1.27 | N6: -4.26 | O6: 4.02 | P6: 12.45 | Q6: 4.63 | R6: -2.27 | S6: 10.47 | T6: 4.8
A7: 1869 | B7: -4.61 | C7: 1.27 | D7: -4.25 | E7: 4.52 | F7: 8.92 | G7: 8.26 | H7: 14.81 | I7: 10.87 | J7: 10.34 | K7: 2.32 | L7: 0.08 | M7: -4.18 | N7: -0.69 | O7: 3.06 | P7: 11.31 | Q7: 4.25 | R7: -0.59 | S7: 9.62 | T7: 4.03
A8: 1870 | B8: -5.46 | C8: -4.23 | D8: -2.59 | E8: 2.79 | F8: 8.9 | G8: 11.41 | H8: 14.39 | I8: 9.84 | J8: 8.16 | K8: 4.07 | L8: -0.15 | M8: -6.81 | N8: -4.62 | O8: 3.03 | P8: 11.88 | Q8: 4.03 | R8: -2.34 | S8: 9.25 | T8: 3.36
A9: 1871 | B9: -7.81 | C9: -1.97 | D9: 0.02 | E9: 3.52 | F9: 6.66 | G9: 7.26 | H9: 13.13 | I9: 12.61 | J9: 11.33 | K9: 3.32 | L9: -2.86 | M9: -8.3 | N9: -5.53 | O9: 3.4 | P9: 11 | Q9: 3.93 | R9: -2.11 | S9: 9.09 | T9: 3.08
A10: 1872 | B10: -3.22 | C10: -2.09 | D10: 0.47 | E10: 3.94 | F10: 6.07 | G10: 10.07 | H10: 13.45 | I10: 10.88 | J10: 10.18 | K10: 5.34 | L10: 1.77 | M10: -0.77 | N10: -4.54 | O10: 3.49 | P10: 11.47 | Q10: 5.76 | R10: -2.11 | S10: 9.1 | T10: 4.67
A11: 1873 | B11: -2.18 | C11: -3.85 | D11: 1.66 | E11: 1.61 | F11: 5.11 | G11: 10.53 | H11: 14.52 | I11: 13.55 | J11: 8.67 | K11: 5.47 | L11: 0.65 | M11: -2.87 | N11: -2.27 | O11: 2.79 | P11: 12.87 | Q11: 4.93 | R11: 0.33 | S11: 9 | T11: 4.4
A12: 1874 | B12: -3.14 | C12: -4.07 | D12: -1.28 | E12: 4.58 | F12: 3.97 | G12: 11.29 | H12: 15.01 | I12: 10.91 | J12: 10.99 | K12: 5.72 | L12: -2.12 | M12: -6.34 | N12: -3.36 | O12: 2.42 | P12: 12.4 | Q12: 4.86 | R12: -0.88 | S12: 9.46 | T12: 3.79
A13: 1875 | B13: -1.76 | C13: -6.47 | D13: -2.13 | E13: 2.89 | F13: 9.5 | G13: 11.38 | H13: 11.44 | I13: 13.57 | J13: 10.64 | K13: 3.81 | L13: -1.15 | M13: -5.52 | N13: -4.86 | O13: 3.42 | P13: 12.13 | Q13: 4.43 | R13: -2.18 | S13: 9.9 | T13: 3.85
A14: 1876 | B14: -4.41 | C14: -2.37 | D14: -0.87 | E14: 2.91 | F14: 4.42 | G14: 10.53 | H14: 13.58 | I14: 13.1 | J14: 7.9 | K14: 7.26 | L14: -1.2 | M14: -0.08 | N14: -4.1 | O14: 2.15 | P14: 12.4 | Q14: 4.66 | R14: -1.75 | S14: 8.74 | T14: 4.23
... A163: 2025 | B163: -0.81 | C163: -0.04 | D163: 2.8 | E163: 6.75 | F163: 9.06 | G163: 16.43 | H163: 14.18 | I163: 15.59 | J163: 10.95 | K163: 6.38 | L163: 1.86 | M163: 0.64 | N163: -0.57 | O163: 6.2 | P163: 15.4 | Q163: 6.4 | R163: 2.06 | S163: 12.16 | T163: 6.98
A164: 2026 | B164: -2.68 | C164: 1.17 | D164: 1.77 | E164: NA | F164: NA | G164: NA | H164: NA | I164: NA | J164: NA | K164: NA | L164: NA | M164: NA | N164: -0.29 | O164: NA | P164: NA | Q164: NA | R164: 1.52 | S164: NA | T164: NA

Sheet Bevölkerung
A1: Jahr | B1: Geschlecht - Total | C1: Mann | D1: Frau
A2: 1986 | B2: 6523413 | C2: 3179911 | D2: 3343502
A3: 1987 | B3: 6566799 | C3: 3201854 | D3: 3364945
A4: 1988 | B4: 6619973 | C4: 3228921 | D4: 3391052
A5: 1989 | B5: 6673850 | C5: 3257537 | D5: 3416313
A6: 1990 | B6: 6750693 | C6: 3298312 | D6: 3452381
A7: 1991 | B7: 6842768 | C7: 3341665 | D7: 3501103
A8: 1992 | B8: 6907959 | C8: 3373916 | D8: 3534043
A9: 1993 | B9: 6968570 | C9: 3403863 | D9: 3564707
A10: 1994 | B10: 7019019 | C10: 3428368 | D10: 3590651
A11: 1995 | B11: 7062354 | C11: 3448842 | D11: 3613512
A12: 1996 | B12: 7081346 | C12: 3457621 | D12: 3623725
A13: 1997 | B13: 7096465 | C13: 3465243 | D13: 3631222
... A40: 2024 | B40: 9051029 | C40: 4500389 | D40: 4550640

Sheet Strom
A1: Monat / Jahr | C1: Landeserzeugung | I1: Verbrauch der | J1: Netto- | K1: Einfuhr | L1: Ausfuhr | M1: Landes- | N1: Verluste | O1: Endverbrauch | P1: Ausfuhr- /
B2: Wasserkraftwerke | C2: Kernkraftwerke | D2: Konv.-therm. und | E2: Thermische | F2: Windkraft- | G2: Photovoltaik- | H2: Total | I2: Speicherpumpen | J2: erzeugung | M2: verbrauch | P2: Einfuhr-
D3: erneuerbare Kraftwerke | E3: Kraftwerke | F3: anlagen | G3: anlagen | K3: ab 2000:physikalisch | L3: ab 2000:physikalisch | P3: Überschuss
F4: revidiert ab 2020
A5: Mois / Année | C5: Production nationale | I5: Pompage | J5: Production | K5: Importation | L5: Exportation | M5: Consommation | N5: Pertes | O5: Consommation | P5: Solde
A6: Monat / Jahr | C6: Landeserzeugung | I6: Verbrauch der | J6: Netto- | K6: Einfuhr | L6: Ausfuhr | M6: Landes- | N6: Verluste | O6: Endverbrauch | P6: Ausfuhr- /
B7: Wasserkraftwerke | C7: Kernkraftwerke | D7: Konv.-therm. und | E7: Thermische | F7: Windkraft- | G7: Photovoltaik- | H7: Total | I7: Speicherpumpen | J7: erzeugung | M7: verbrauch | P7: Einfuhr-
D8: erneuerbare Kraftwerke | E8: Kraftwerke | F8: anlagen | G8: anlagen | K8: ab 2000:physikalisch | L8: ab 2000:physikalisch | P8: Überschuss
F9: revidiert ab 2020
A10: Mois / Année | C10: Production nationale | I10: Pompage | J10: Production | K10: Importation | L10: Exportation | M10: Consommation | N10: Pertes | O10: Consommation | P10: Solde
B11: Centrales | C11: Centrales | D11: Centrales | E11: Centrales | F11: Éoliennes | G11: Installations | H11: Total | I11: d'acccumulation | J11: nette | M11: du pays | O11: finale | P11: exportateur /
B12: hydrauliques | C12: nucléaires | D12: thermiques classique | E12: thermiques | G12: photovoltaïques | K12: dès 2000:physique | L12: dès 2000:physique | P12: importateur
D13: et renouvelables | F13: révisé dès 2020
A15: Januar / Janvier 1990 | B15: 2009 | C15: 2185 | D15: 134 | E15: n.a. | F15: n.a. | G15: n.a. | H15: 4328 | I15: 49 | J15: 4279 | K15: 2616 | L15: 1974 | M15: 4921 | N15: 332 | O15: 4589 | P15: 642
A16: Februar / Février 1990 | B16: 1805 | C16: 1964 | D16: 160 | E16: n.a. | F16: n.a. | G16: n.a. | H16: 3929 | I16: 67 | J16: 3862 | K16: 2113 | L16: 1741 | M16: 4234 | N16: 313 | O16: 3921 | P16: 372
A17: März / Mars 1990 | B17: 2437 | C17: 2172 | D17: 127 | E17: n.a. | F17: n.a. | G17: n.a. | H17: 4736 | I17: 40 | J17: 4696 | K17: 1895 | L17: 2100 | M17: 4491 | N17: 334 | O17: 4157 | P17: -205
A18: April / Avril 1990 | B18: 2220 | C18: 2105 | D18: 72 | E18: n.a. | F18: n.a. | G18: n.a. | H18: 4397 | I18: 62 | J18: 4335 | K18: 1799 | L18: 2015 | M18: 4119 | N18: 323 | O18: 3796 | P18: -216
A19: Mai / Mai 1990 | B19: 2897 | C19: 1940 | D19: 60 | E19: n.a. | F19: n.a. | G19: n.a. | H19: 4897 | I19: 249 | J19: 4648 | K19: 1423 | L19: 2202 | M19: 3869 | N19: 288 | O19: 3581 | P19: -779
A20: Juni / Juin 1990 | B20: 3381 | C20: 1188 | D20: 54 | E20: n.a. | F20: n.a. | G20: n.a. | H20: 4623 | I20: 212 | J20: 4411 | K20: 1521 | L20: 2158 | M20: 3774 | N20: 261 | O20: 3513 | P20: -637
A21: Juli / Juillet 1990 | B21: 3570 | C21: 1592 | D21: 61 | E21: n.a. | F21: n.a. | G21: n.a. | H21: 5223 | I21: 321 | J21: 4902 | K21: 1287 | L21: 2557 | M21: 3632 | N21: 286 | O21: 3346 | P21: -1270
A22: August / Août 1990 | B22: 3103 | C22: 910 | D22: 55 | E22: n.a. | F22: n.a. | G22: n.a. | H22: 4068 | I22: 305 | J22: 3763 | K22: 1735 | L22: 1850 | M22: 3648 | N22: 275 | O22: 3373 | P22: -115
A23: September / Septembre 1990 | B23: 2337 | C23: 1831 | D23: 61 | E23: n.a. | F23: n.a. | G23: n.a. | H23: 4229 | I23: 172 | J23: 4057 | K23: 1921 | L23: 2173 | M23: 3805 | N23: 279 | O23: 3526 | P23: -252
A24: Oktober / Octobre 1990 | B24: 2288 | C24: 2131 | D24: 81 | E24: n.a. | F24: n.a. | G24: n.a. | H24: 4500 | I24: 92 | J24: 4408 | K24: 2107 | L24: 2228 | M24: 4287 | N24: 320 | O24: 3967 | P24: -121
A25: November / Novembre 1990 | B25: 2371 | C25: 2107 | D25: 112 | E25: n.a. | F25: n.a. | G25: n.a. | H25: 4590 | I25: 64 | J25: 4526 | K25: 2056 | L25: 1949 | M25: 4633 | N25: 334 | O25: 4299 | P25: 107
A26: Dezember / Décembre 1990 | B26: 2257 | C26: 2173 | D26: 124 | E26: n.a. | F26: n.a. | G26: n.a. | H26: 4554 | I26: 62 | J26: 4492 | K26: 2326 | L26: 1960 | M26: 4858 | N26: 348 | O26: 4510 | P26: 366
... A266: Dezember / Décembre 2010 | B266: 3169 | C266: 2445 | D266: 290 | E266: n.a. | F266: n.a. | G266: n.a. | H266: 5904 | I266: 146 | J266: 5758 | K266: 3167 | L266: 2629 | M266: 6296 | N266: 422 | O266: 5874 | P266: 538
A267: Januar / Janvier 2011 | B267: 2652 | C267: 2435 | D267: 321 | E267: n.a. | F267: n.a. | G267: n.a. | H267: 5408 | I267: 144 | J267: 5264 | K267: 3682 | L267: 2733 | M267: 6213 | N267: 392 | O267: 5821 | P267: 949 | Q267: revidiert / révisé
A268: Februar / Février 2011 | B268: 2228 | C268: 2177 | D268: 311 | E268: n.a. | F268: n.a. | G268: n.a. | H268: 4716 | I268: 99 | J268: 4617 | K268: 3733 | L268: 2743 | M268: 5607 | N268: 394 | O268: 5213 | P268: 990
A269: März / Mars 2011 | B269: 2032 | C269: 2426 | D269: 321 | E269: n.a. | F269: n.a. | G269: n.a. | H269: 4779 | I269: 167 | J269: 4612 | K269: 3726 | L269: 2526 | M269: 5812 | N269: 399 | O269: 5413 | P269: 1200
A270: April / Avril 2011 | B270: 2142 | C270: 2321 | D270: 291 | E270: n.a. | F270: n.a. | G270: n.a. | H270: 4754 | I270: 189 | J270: 4565 | K270: 2758 | L270: 2494 | M270: 4829 | N270: 366 | O270: 4463 | P270: 264
A271: Mai / Mai 2011 | B271: 2795 | C271: 2397 | D271: 264 | E271: n.a. | F271: n.a. | G271: n.a. | H271: 5456 | I271: 238 | J271: 5218 | K271: 2143 | L271: 2421 | M271: 4940 | N271: 353 | O271: 4587 | P271: -278
A272: Juni / Juin 2011 | B272: 3392 | C272: 1561 | D272: 257 | E272: n.a. | F272: n.a. | G272: n.a. | H272: 5210 | I272: 332 | J272: 4878 | K272: 2265 | L272: 2489 | M272: 4654 | N272: 312 | O272: 4342 | P272: -224
A273: Juli / Juillet 2011 | B273: 3663 | C273: 2057 | D273: 310 | E273: n.a. | F273: n.a. | G273: n.a. | H273: 6030 | I273: 376 | J273: 5654 | K273: 2124 | L273: 3135 | M273: 4643 | N273: 349 | O273: 4294 | P273: -1011
A274: August / Août 2011 | B274: 3518 | C274: 1151 | D274: 285 | E274: n.a. | F274: n.a. | G274: n.a. | H274: 4954 | I274: 315 | J274: 4639 | K274: 2181 | L274: 2098 | M274: 4722 | N274: 348 | O274: 4374 | P274: 83
A275: September / Septembre 2011 | B275: 3539 | C275: 1835 | D275: 269 | E275: n.a. | F275: n.a. | G275: n.a. | H275: 5643 | I275: 195 | J275: 5448 | K275: 1852 | L275: 2495 | M275: 4805 | N275: 335 | O275: 4470 | P275: -643
A276: Oktober / Octobre 2011 | B276: 2772 | C276: 2397 | D276: 286 | E276: n.a. | F276: n.a. | G276: n.a. | H276: 5455 | I276: 122 | J276: 5333 | K276: 3028 | L276: 3135 | M276: 5226 | N276: 379 | O276: 4847 | P276: -107
A277: November / Novembre 2011 | B277: 2535 | C277: 2361 | D277: 300 | E277: n.a. | F277: n.a. | G277: n.a. | H277: 5196 | I277: 120 | J277: 5076 | K277: 3532 | L277: 2988 | M277: 5620 | N277: 378 | O277: 5242 | P277: 544
A278: Dezember / Décembre 2011 | B278: 2527 | C278: 2442 | D278: 311 | E278: n.a. | F278: n.a. | G278: n.a. | H278: 5280 | I278: 169 | J278: 5111 | K278: 3800 | L278: 2980 | M278: 5931 | N278: 398 | O278: 5533 | P278: 820
A279: Januar / Janvier 2012 | B279: 2796 | C279: 2437 | D279: 310 | E279: n.a. | F279: n.a. | G279: n.a. | H279: 5543 | I279: 133 | J279: 5410 | K279: 3616 | L279: 2900 | M279: 6126 | N279: 386 | O279: 5740 | P279: 716
... A314: Dezember / Décembre 2014 | B314: 3126 | C314: 2474 | D314: 364 | E314: n.a. | F314: n.a. | G314: n.a. | H314: 5964 | I314: 117 | J314: 5847 | K314: 3054 | L314: 3032 | M314: 5869 | N314: 393 | O314: 5476 | P314: 22
...
